Workbook

Sheet Petunjuk
A1: KONSEP FORMAT EXCEL LAPORAN PENGGUNAAN DANA HARIAN (LPDH) SPPG
A2: Lampiran pendukung Konsep SE Pelaksanaan HPE dan Pemberian Insentif Ketersediaan dan Mutu Layanan SPPG | Versi 4, memuat koreksi Tim PPK dan lembar pengesahan
A4: KETERANGAN WARNA
A5: Sel kuning, huruf biru | B5: Diisi oleh SPPG (Pengawas Keuangan bersama Kepala SPPG).
A6: Sel biru muda, huruf biru | B6: Diisi oleh Tim PPK (persetujuan top up, parameter, indeks kemahalan).
A7: Sel putih, huruf hitam | B7: Rumus otomatis; jangan diubah.
A8: Hijau / jingga | B8: OK atau Unik/Sesuai/Lengkap = sesuai; jingga = PERIKSA, DUPLIKAT, DI LUAR PERIODE, BELUM LENGKAP, atau BELUM ADA LINK.
A10: URUTAN PENGISIAN
A11: 1. Identitas | B11: Identitas SPPG, tanggal, status hari, HPE ke-, waktu unggah, serta penanda tangan: Pengawas Keuangan (nama dan NIK), Kepala SPPG (nama dan NIP), dan Perwakilan Mitra/Yayasan yang menyetujui (nama dan NIK). Indeks kemahalan dan periode transaksi terisi otomatis.
A12: 2. A_PM | B12: Per kelompok sasaran: target SPS, distribusi (POP), penerimaan PIC PM dan tidak diterima (Fleet), BNBA, nomor BAST, dan link bukti autentik BAST di Cloud SIPGN. Lalu rekonsiliasi POP dan Fleet.
A13: 3. B_BahanBaku | B13: Satu baris per transaksi: tanggal, nomor bukti unik, link bukti autentik.
A14: 4. C1_Relawan | B14: Daftar nominatif pembayaran insentif relawan: nama, nominal, nomor bukti pembayaran, link bukti bayar.
A15: 5. C_Operasional | B15: Biaya operasional lainnya: tanggal, nomor bukti unik, link bukti. Baris insentif relawan terisi otomatis dari C1_Relawan.
A16: 6. D_Insentif | B16: Syarat Insentif dan pembayaran harian ke Mitra/Yayasan: nominal, tanggal, nomor bukti pembayaran, kuitansi bertanda tangan Mitra, link PDF bukti bayar.
A17: 7. E_Saldo | B17: Saldo awal, rincian penerimaan top up (tanggal, nilai per komponen, nomor kuitansi/bukti terima, link), dan saldo VA.
A18: 8. F_TopUp | B18: Usulan SPPG otomatis; persetujuan diisi Tim PPK.
A19: 9. G_CekPPK | B19: Seluruh butir harus OK sebelum diunggah; dipakai Tim PPK untuk verifikasi.
A20: 10. H_RekapPPK dan I_RegisterBukti | B20: Satu baris ringkasan dan register nomor bukti untuk konsolidasi serta uji duplikasi lintas hari/lintas SPPG.
A21: 11. J_Pengesahan | B21: Lembar yang dicetak dan ditandatangani tiga pihak (Disusun oleh, Mengetahui, Menyetujui), dicap SPPG dan Yayasan, lalu dipindai menjadi PDF. Nama dan NIK/NIP terisi otomatis dari Identitas.
A23: KETENTUAN BUKTI TRANSAKSI
A24: Bukti autentik | B24: Setiap transaksi bernilai wajib memiliki link https:// ke berkas yang diunggah di Cloud SIPGN (PDF/foto kuitansi, nota, bukti transfer, BAST).
A25: Nomor bukti unik | B25: Nomor bukti tidak boleh sama dengan transaksi lain. Satu nota berisi beberapa item ditulis dengan sufiks (NT-004/1, NT-004/2). Kode unik transaksi dibentuk otomatis: ID SPPG-tanggal-jenis-urutan.
A26: Tanggal transaksi | B26: Harus berada dalam periode transaksi (Identitas!B32:B33): tanggal pelayanan dikurangi toleransi pada Ref sampai tanggal pelayanan.
A27: Indeks kemahalan | B27: Pagu bahan baku dan operasional disesuaikan dengan indeks kemahalan Kab/Kota (lembar Ref, diisi PPK). Tarif Insentif Rp2.000 tidak disesuaikan.
A29: KETENTUAN PENYAMPAIAN
A30: Tanda tangan | B30: Pengawas Keuangan (NIK 16 digit) menyusun, Kepala SPPG (NIP 18 digit) mengetahui, Perwakilan Mitra/Yayasan (NIK 16 digit) menyetujui. Tanda tangan basah dibubuhkan pada lembar J_Pengesahan.
A31: Bentuk berkas | B31: PDF hasil pindai lembar J_Pengesahan dan lembar laporan yang ditandatangani dan dicap, serta berkas Excel ini tanpa mengubah susunan kolom, baris, dan rumus.
A32: Nama berkas | B32: [ID SPPG]_[Nama SPPG]_LPDH_[TTTTBBHH]: lihat Identitas!B29.
A33: Batas waktu | B33: Diunggah melalui SIPGN paling lambat H+1 pukul 06.00 waktu setempat.
A35: CATATAN
A36: Data contoh | B36: Isian kuning, link cloud-sipgn.contoh, dan indeks kemahalan di Ref adalah CONTOH fiktif. Ganti dengan data dan tautan riil.
A37: Status konsep | B37: Konsep untuk dibahas dengan Tim PPK dan Pengelola SIPGN; struktur kolom dapat disesuaikan dengan modul unggah SIPGN.

Sheet Identitas
A1: LAPORAN PENGGUNAAN DANA HARIAN (LPDH): IDENTITAS
A2: Program Makan Bergizi Gratis TA 2026 | Isi sel kuning
A4: Uraian | B4: Isian
A5: Nomor LPDH | B5: 001/LPDH/SPPG-X/X/2026
A6: ID SPPG | B6: 18.71.XX.XXXX
A7: Nama SPPG | B7: SPPG Contoh 1
A8: Desa/Kelurahan | B8: Contoh
A9: Kecamatan | B9: Contoh
A10: Kabupaten/Kota | B10: Kota Contoh
A11: Provinsi | B11: Lampung
A12: Nama Mitra/Yayasan | B12: Yayasan Contoh
A13: Nomor VA | B13: XXXXXXXXXXXX
A14: Bank Himbara | B14: Bank Contoh
A15: Tanggal Pelayanan | B15: 46300
A16: Hari | B16: =IF(B15="","",CHOOSE(WEEKDAY(B15),"Minggu","Senin","Selasa","Rabu","Kamis","Jumat","Sabtu")) -> Senin
A17: Minggu ke- (dalam bulan) | B17: 1
A18: Status Hari | B18: HPE
A19: HPE ke- pada minggu berkenaan (1–5) | B19: 1
A20: Dihitung sebagai HPE? | B20: {=IF(AND(INDEX(Ref!$B$34:$B$39,MATCH(B18,Ref!$A$34:$A$39,0))="Ya",B19>=1,B19<=Ref!$B$10),"Ya","Tidak")} -> Ya
A21: Indeks kemahalan harga Kab/Kota (otomatis dari Ref) | B21: {=IFERROR(INDEX(Ref!$C$64:$C$213,MATCH(B10,Ref!$B$64:$B$213,0)),1)} -> 1.05
A22: Sumber indeks kemahalan | B22: {=IFERROR(INDEX(Ref!$D$64:$D$213,MATCH(B10,Ref!$B$64:$B$213,0)),"Belum tercantum di Ref: dipakai 100%")} -> CONTOH: diganti dengan indeks resmi yang ditetapkan
A24: Pengunggahan | B24: Isian
A25: Tanggal unggah ke SIPGN | B25: 46301
A26: Jam unggah (jj:mm) | B26: 0.22916667
A27: Batas unggah | B27: =B15+1+TIME(Ref!$B$11,0,0) -> 46301.25
A28: Tepat waktu? | B28: =IF(OR(B25="",B26=""),"Belum diunggah",IF(B25+B26<=B27,"Ya","Terlambat")) -> Ya
A29: Nama berkas (otomatis) | B29: =B6&"_"&B7&"_LPDH_"&TEXT(B15,"yyyymmdd") -> 18.71.XX.XXXX_SPPG Contoh 1_LPDH_20261005
A31: Periode Transaksi yang Sah | B31: Tanggal
A32: Dari (tanggal pelayanan − toleransi pada Ref) | B32: =B15-Ref!$B$13 -> 46299
A33: Sampai (tanggal pelayanan) | B33: =B15 -> 46300
A35: Penanda Tangan | B35: Nama Lengkap | C35: Jenis Identitas | D35: Nomor Identitas | E35: Status Identitas | F35: Sudah tanda tangan (Ya/Tidak)
A36: Disusun oleh: Pengawas Keuangan SPPG | B36: Nama Pengawas Keuangan | C36: NIK | D36: 1871000000000001 | E36: =IF(D36="","BELUM DIISI",IF(AND(LEN(D36)=16,ISNUMBER(--D36)),"Valid","PERIKSA: NIK harus 16 digit angka")) -> Valid | F36: Ya
A37: Mengetahui: Kepala SPPG | B37: Nama Kepala SPPG | C37: NIP | D37: 199001012026011001 | E37: =IF(D37="","BELUM DIISI",IF(AND(LEN(D37)=18,ISNUMBER(--D37)),"Valid","PERIKSA: NIP harus 18 digit angka")) -> Valid | F37: Ya
A38: Menyetujui: Perwakilan Mitra/Yayasan | B38: Nama Perwakilan Yayasan | C38: NIK | D38: 1871000000000002 | E38: =IF(D38="","BELUM DIISI",IF(AND(LEN(D38)=16,ISNUMBER(--D38)),"Valid","PERIKSA: NIK harus 16 digit angka")) -> Valid | F38: Ya
A39: NIK 16 digit (Pengawas Keuangan dan Perwakilan Yayasan); NIP 18 digit (Kepala SPPG). Nomor contoh fiktif, ganti dengan data riil. Nama dan nomor identitas otomatis tercetak pada lembar J_Pengesahan.

Sheet A_PM
A1: A. PRODUKSI, DISTRIBUSI, DAN PENERIMAAN PORSI (APLIKASI POP DAN FLEET)
A2: Produksi dari Aplikasi POP; penerimaan PIC PM dari Aplikasi Fleet. PM dihitung hanya bila HPE, BNBA tersedia, nomor BAST terisi, dan bukti autentik BAST ter-link ke Cloud SIPGN.
A5: Kode | B5: Kelompok Sasaran | C5: Kategori Porsi | D5: Jenis PIC | E5: Target PM (SPS) | F5: Didistribusikan ke PM (POP) | G5: Diterima PIC PM (Fleet) | H5: Tidak Diterima (Fleet) | I5: Alasan Tidak Diterima | J5: Selisih Distribusi | K5: Data BNBA Tersedia | L5: No. BAST/Tanda Terima | M5: Link Bukti Autentik BAST (Cloud SIPGN) | N5: Status Bukti BAST | O5: PM Dihitung | P5: Capaian thd Target | Q5: Pagu Bahan/Porsi Disesuaikan (Rp) | R5: Keterangan
A6: KS-01 | B6: PAUD/TK/RA | C6: Kecil | D6: Sekolah | E6: 210 | F6: 210 | G6: 205 | H6: 5 | I6: PM tidak hadir | J6: =F6-G6-H6 -> 0 | K6: Ya | L6: BAST-01 | M6: https://cloud-sipgn.contoh/lpdh/bast/BAST-01.pdf | N6: =IF(N(G6)=0,"",IF(AND(L6<>"",LEFT(M6,8)="https://"),"Terlampir","BELUM ADA LINK")) -> Terlampir | O6: =IF(AND(Identitas!$B$20="Ya",K6="Ya",N6="Terlampir"),G6,0) -> 205 | P6: =IF(N(E6)>0,O6/E6,"") -> 0.97619048 | Q6: {=INDEX(Ref!$D$19:$D$28,MATCH(A6,Ref!$A$19:$A$28,0))*IF(Ref!$B$14="Ya",Identitas!$B$21,1)} -> 8400
A7: KS-02 | B7: SD/MI Kelas 1–3 | C7: Kecil | D7: Sekolah | E7: 650 | F7: 650 | G7: 640 | H7: 10 | I7: Kualitas tidak layak/tidak standar | J7: =F7-G7-H7 -> 0 | K7: Ya | L7: BAST-02 | M7: https://cloud-sipgn.contoh/lpdh/bast/BAST-02.pdf | N7: =IF(N(G7)=0,"",IF(AND(L7<>"",LEFT(M7,8)="https://"),"Terlampir","BELUM ADA LINK")) -> Terlampir | O7: =IF(AND(Identitas!$B$20="Ya",K7="Ya",N7="Terlampir"),G7,0) -> 640 | P7: =IF(N(E7)>0,O7/E7,"") -> 0.98461538 | Q7: {=INDEX(Ref!$D$19:$D$28,MATCH(A7,Ref!$A$19:$A$28,0))*IF(Ref!$B$14="Ya",Identitas!$B$21,1)} -> 8400
A8: KS-03 | B8: SD/MI Kelas 4–6 | C8: Besar | D8: Sekolah | E8: 600 | F8: 600 | G8: 592 | H8: 8 | I8: PM tidak hadir | J8: =F8-G8-H8 -> 0 | K8: Ya | L8: BAST-03 | M8: https://cloud-sipgn.contoh/lpdh/bast/BAST-03.pdf | N8: =IF(N(G8)=0,"",IF(AND(L8<>"",LEFT(M8,8)="https://"),"Terlampir","BELUM ADA LINK")) -> Terlampir | O8: =IF(AND(Identitas!$B$20="Ya",K8="Ya",N8="Terlampir"),G8,0) -> 592 | P8: =IF(N(E8)>0,O8/E8,"") -> 0.98666667 | Q8: {=INDEX(Ref!$D$19:$D$28,MATCH(A8,Ref!$A$19:$A$28,0))*IF(Ref!$B$14="Ya",Identitas!$B$21,1)} -> 10500
A9: KS-04 | B9: SMP/MTs | C9: Besar | D9: Sekolah | E9: 520 | F9: 520 | G9: 515 | H9: 5 | I9: PM tidak hadir | J9: =F9-G9-H9 -> 0 | K9: Ya | L9: BAST-04 | M9: https://cloud-sipgn.contoh/lpdh/bast/BAST-04.pdf | N9: =IF(N(G9)=0,"",IF(AND(L9<>"",LEFT(M9,8)="https://"),"Terlampir","BELUM ADA LINK")) -> Terlampir | O9: =IF(AND(Identitas!$B$20="Ya",K9="Ya",N9="Terlampir"),G9,0) -> 515 | P9: =IF(N(E9)>0,O9/E9,"") -> 0.99038462 | Q9: {=INDEX(Ref!$D$19:$D$28,MATCH(A9,Ref!$A$19:$A$28,0))*IF(Ref!$B$14="Ya",Identitas!$B$21,1)} -> 10500
A10: KS-05 | B10: SMA/MA/SMK/SLB | C10: Besar | D10: Sekolah | E10: 0 | F10: 0 | G10: 0 | H10: 0 | J10: =F10-G10-H10 -> 0 | N10: =IF(N(G10)=0,"",IF(AND(L10<>"",LEFT(M10,8)="https://"),"Terlampir","BELUM ADA LINK")) | O10: =IF(AND(Identitas!$B$20="Ya",K10="Ya",N10="Terlampir"),G10,0) -> 0 | P10: =IF(N(E10)>0,O10/E10,"") | Q10: {=INDEX(Ref!$D$19:$D$28,MATCH(A10,Ref!$A$19:$A$28,0))*IF(Ref!$B$14="Ya",Identitas!$B$21,1)} -> 10500
A11: KS-06 | B11: Santri | C11: Besar | D11: Sekolah | E11: 0 | F11: 0 | G11: 0 | H11: 0 | J11: =F11-G11-H11 -> 0 | N11: =IF(N(G11)=0,"",IF(AND(L11<>"",LEFT(M11,8)="https://"),"Terlampir","BELUM ADA LINK")) | O11: =IF(AND(Identitas!$B$20="Ya",K11="Ya",N11="Terlampir"),G11,0) -> 0 | P11: =IF(N(E11)>0,O11/E11,"") | Q11: {=INDEX(Ref!$D$19:$D$28,MATCH(A11,Ref!$A$19:$A$28,0))*IF(Ref!$B$14="Ya",Identitas!$B$21,1)} -> 10500
A12: KS-07 | B12: Ibu Hamil | C12: Besar | D12: 3B | E12: 35 | F12: 35 | G12: 33 | H12: 2 | I12: PM tidak hadir | J12: =F12-G12-H12 -> 0 | K12: Ya | L12: BAST-05 | M12: https://cloud-sipgn.contoh/lpdh/bast/BAST-05.pdf | N12: =IF(N(G12)=0,"",IF(AND(L12<>"",LEFT(M12,8)="https://"),"Terlampir","BELUM ADA LINK")) -> Terlampir | O12: =IF(AND(Identitas!$B$20="Ya",K12="Ya",N12="Terlampir"),G12,0) -> 33 | P12: =IF(N(E12)>0,O12/E12,"") -> 0.94285714 | Q12: {=INDEX(Ref!$D$19:$D$28,MATCH(A12,Ref!$A$19:$A$28,0))*IF(Ref!$B$14="Ya",Identitas!$B$21,1)} -> 10500
A13: KS-08 | B13: Ibu Menyusui | C13: Besar | D13: 3B | E13: 45 | F13: 45 | G13: 44 | H13: 1 | I13: PM tidak hadir | J13: =F13-G13-H13 -> 0 | K13: Ya | L13: BAST-06 | M13: https://cloud-sipgn.contoh/lpdh/bast/BAST-06.pdf | N13: =IF(N(G13)=0,"",IF(AND(L13<>"",LEFT(M13,8)="https://"),"Terlampir","BELUM ADA LINK")) -> Terlampir | O13: =IF(AND(Identitas!$B$20="Ya",K13="Ya",N13="Terlampir"),G13,0) -> 44 | P13: =IF(N(E13)>0,O13/E13,"") -> 0.97777778 | Q13: {=INDEX(Ref!$D$19:$D$28,MATCH(A13,Ref!$A$19:$A$28,0))*IF(Ref!$B$14="Ya",Identitas!$B$21,1)} -> 10500
A14: KS-09 | B14: Anak Balita (6–59 bulan) | C14: Kecil | D14: 3B | E14: 190 | F14: 190 | G14: 186 | H14: 4 | I14: Kemasan rusak/tumpah | J14: =F14-G14-H14 -> 0 | K14: Ya | L14: BAST-07 | M14: https://cloud-sipgn.contoh/lpdh/bast/BAST-07.pdf | N14: =IF(N(G14)=0,"",IF(AND(L14<>"",LEFT(M14,8)="https://"),"Terlampir","BELUM ADA LINK")) -> Terlampir | O14: =IF(AND(Identitas!$B$20="Ya",K14="Ya",N14="Terlampir"),G14,0) -> 186 | P14: =IF(N(E14)>0,O14/E14,"") -> 0.97894737 | Q14: {=INDEX(Ref!$D$19:$D$28,MATCH(A14,Ref!$A$19:$A$28,0))*IF(Ref!$B$14="Ya",Identitas!$B$21,1)} -> 8400
A15: PTK | B15: Pendidik dan Tenaga Kependidikan | C15: Besar | D15: Sekolah | E15: 120 | F15: 120 | G15: 118 | H15: 2 | I15: PM tidak hadir | J15: =F15-G15-H15 -> 0 | K15: Ya | L15: BAST-08 | M15: https://cloud-sipgn.contoh/lpdh/bast/BAST-08.pdf | N15: =IF(N(G15)=0,"",IF(AND(L15<>"",LEFT(M15,8)="https://"),"Terlampir","BELUM ADA LINK")) -> Terlampir | O15: =IF(AND(Identitas!$B$20="Ya",K15="Ya",N15="Terlampir"),G15,0) -> 118 | P15: =IF(N(E15)>0,O15/E15,"") -> 0.98333333 | Q15: {=INDEX(Ref!$D$19:$D$28,MATCH(A15,Ref!$A$19:$A$28,0))*IF(Ref!$B$14="Ya",Identitas!$B$21,1)} -> 10500
A16: JUMLAH | E16: =SUM(E6:E15) -> 2370 | F16: =SUM(F6:F15) -> 2370 | G16: =SUM(G6:G15) -> 2333 | H16: =SUM(H6:H15) -> 37 | J16: =SUM(J6:J15) -> 0 | O16: =SUM(O6:O15) -> 2333 | P16: =IF(E16>0,O16/E16,"") -> 0.98438819 | Q16: =IF(F16>0,SUMPRODUCT(F6:F15,Q6:Q15)/F16,0) -> 9569.6203 | R16: ← Q: pagu bahan tertimbang setelah indeks kemahalan
A18: 1. PRODUKSI (APLIKASI POP) | C18: Jumlah Porsi | D18: Sumber/Keterangan
A19: Total porsi diproduksi | C19: 2400 | D19: Aplikasi POP: total produksi hari ini
A20: a. Didistribusikan kepada PM | C20: =F16 -> 2370 | D20: Jumlah kolom F
A21: b. Uji organoleptik | C21: 3 | D21: Aplikasi POP
A22: c. Sampel makanan (retained sample) | C22: 3 | D22: Aplikasi POP
A23: d. Tidak terdistribusi | C23: 4 | D23: Aplikasi POP: sisa produksi yang tidak dikirim
A24: e. Buffer produksi | C24: 20 | D24: Aplikasi POP: cadangan produksi
A25: Jumlah a s.d. e | C25: =SUM(C20:C24) -> 2400
A26: Selisih produksi (harus 0) | C26: =C19-C25 -> 0 | D26: Total diproduksi − (a+b+c+d+e)
A27: Persentase buffer terhadap produksi | C27: =IF(C19>0,C24/C19,0) -> 0.0083333333 | D27: Dibandingkan batas buffer pada lembar Ref
A29: 2. PENERIMAAN (APLIKASI FLEET) | C29: Jumlah Porsi | D29: Sumber/Keterangan
A30: Diterima PIC PM sekolah | C30: =SUMIF(D6:D15,"Sekolah",G6:G15) -> 2070 | D30: Satuan pendidikan (termasuk PTK)
A31: Diterima PIC PM 3B | C31: =SUMIF(D6:D15,"3B",G6:G15) -> 263 | D31: Posyandu/kader (ibu hamil, ibu menyusui, balita)
A32: Total diterima PIC PM | C32: =C30+C31 -> 2333
A33: Total tidak diterima | C33: =H16 -> 37 | D33: Jumlah kolom H; rincian alasan di bawah
A34: • Kualitas tidak layak/tidak standar | C34: =SUMIF(I6:I15,"Kualitas tidak layak/tidak standar",H6:H15) -> 10 | D34: Rincian alasan dari Aplikasi Fleet
A35: • Kemasan rusak/tumpah | C35: =SUMIF(I6:I15,"Kemasan rusak/tumpah",H6:H15) -> 4 | D35: Rincian alasan dari Aplikasi Fleet
A36: • PM tidak hadir | C36: =SUMIF(I6:I15,"PM tidak hadir",H6:H15) -> 23 | D36: Rincian alasan dari Aplikasi Fleet
A37: • Libur/kegiatan mendadak | C37: =SUMIF(I6:I15,"Libur/kegiatan mendadak",H6:H15) -> 0 | D37: Rincian alasan dari Aplikasi Fleet
A38: • Keterlambatan pengiriman | C38: =SUMIF(I6:I15,"Keterlambatan pengiriman",H6:H15) -> 0 | D38: Rincian alasan dari Aplikasi Fleet
A39: • Kelebihan kirim/dikembalikan | C39: =SUMIF(I6:I15,"Kelebihan kirim/dikembalikan",H6:H15) -> 0 | D39: Rincian alasan dari Aplikasi Fleet
A40: • Lainnya | C40: =SUMIF(I6:I15,"Lainnya",H6:H15) -> 0 | D40: Rincian alasan dari Aplikasi Fleet
A41: Kesesuaian POP vs Fleet (harus 0) | C41: =C20-(C32+C33) -> 0 | D41: Didistribusikan (POP) − (diterima + tidak diterima (Fleet))
A43: 3. DASAR PENGHITUNGAN INSENTIF | C43: Jumlah Porsi | D43: Sumber/Keterangan
A44: PM dihitung dari kelompok sasaran | C44: =O16 -> 2333 | D44: Diterima PIC PM, ber-BNBA, ber-BAST, dan bukti BAST ter-link
A45: Porsi uji organoleptik | C45: =IF(Identitas!$B$20="Ya",C21,0) -> 3 | D45: Diperhitungkan sesuai konsep SE butir E.3.b
...

Sheet B_BahanBaku
A1: B. RINCIAN BELANJA BAHAN BAKU PANGAN (AT COST)
A2: Setiap baris = satu transaksi dengan nomor bukti unik dan link bukti autentik. Bila satu nota memuat beberapa item, gunakan nomor nota + urutan item (contoh NT-004/1, NT-004/2).
A5: No | B5: Kode Unik Transaksi (otomatis) | C5: Tanggal Transaksi | D5: Nama Bahan | E5: Kategori | F5: Volume | G5: Satuan | H5: Harga Satuan (Rp) | I5: Jumlah (Rp) | J5: Nama Pemasok | K5: No. Bukti/Nota | L5: Link Bukti Autentik (Cloud SIPGN) | M5: Status Nomor Bukti | N5: Status Tanggal | O5: Keterangan
A6: 1 | B6: =IF(D6="","",Identitas!$B$6&"-"&TEXT(Identitas!$B$15,"yyyymmdd")&"-BB-"&TEXT(A6,"000")) -> 18.71.XX.XXXX-20261005-BB-001 | C6: 46299 | D6: Beras | E6: Karbohidrat | F6: 180 | G6: kg | H6: 14000 | I6: =IF(OR(F6="",H6=""),0,F6*H6) -> 2520000 | J6: Pemasok A | K6: NT-001 | L6: https://cloud-sipgn.contoh/lpdh/bb/NT-001.pdf | M6: =IF(K6="","",IF(COUNTIF(I_RegisterBukti!$C$5:$C$130,K6)>1,"DUPLIKAT","Unik")) -> Unik | N6: =IF(D6="","",IF(C6="","TANGGAL KOSONG",IF(AND(C6>=Identitas!$B$32,C6<=Identitas!$B$33),"Sesuai","DI LUAR PERIODE"))) -> Sesuai
A7: 2 | B7: =IF(D7="","",Identitas!$B$6&"-"&TEXT(Identitas!$B$15,"yyyymmdd")&"-BB-"&TEXT(A7,"000")) -> 18.71.XX.XXXX-20261005-BB-002 | C7: 46299 | D7: Daging ayam | E7: Protein hewani | F7: 240 | G7: kg | H7: 38000 | I7: =IF(OR(F7="",H7=""),0,F7*H7) -> 9120000 | J7: Pemasok B | K7: NT-002 | L7: https://cloud-sipgn.contoh/lpdh/bb/NT-002.pdf | M7: =IF(K7="","",IF(COUNTIF(I_RegisterBukti!$C$5:$C$130,K7)>1,"DUPLIKAT","Unik")) -> Unik | N7: =IF(D7="","",IF(C7="","TANGGAL KOSONG",IF(AND(C7>=Identitas!$B$32,C7<=Identitas!$B$33),"Sesuai","DI LUAR PERIODE"))) -> Sesuai
A8: 3 | B8: =IF(D8="","",Identitas!$B$6&"-"&TEXT(Identitas!$B$15,"yyyymmdd")&"-BB-"&TEXT(A8,"000")) -> 18.71.XX.XXXX-20261005-BB-003 | C8: 46299 | D8: Tahu | E8: Protein nabati | F8: 600 | G8: potong | H8: 700 | I8: =IF(OR(F8="",H8=""),0,F8*H8) -> 420000 | J8: Pemasok C | K8: NT-003 | L8: https://cloud-sipgn.contoh/lpdh/bb/NT-003.pdf | M8: =IF(K8="","",IF(COUNTIF(I_RegisterBukti!$C$5:$C$130,K8)>1,"DUPLIKAT","Unik")) -> Unik | N8: =IF(D8="","",IF(C8="","TANGGAL KOSONG",IF(AND(C8>=Identitas!$B$32,C8<=Identitas!$B$33),"Sesuai","DI LUAR PERIODE"))) -> Sesuai
A9: 4 | B9: =IF(D9="","",Identitas!$B$6&"-"&TEXT(Identitas!$B$15,"yyyymmdd")&"-BB-"&TEXT(A9,"000")) -> 18.71.XX.XXXX-20261005-BB-004 | C9: 46299 | D9: Wortel | E9: Sayuran | F9: 80 | G9: kg | H9: 12000 | I9: =IF(OR(F9="",H9=""),0,F9*H9) -> 960000 | J9: Pemasok D | K9: NT-004/1 | L9: https://cloud-sipgn.contoh/lpdh/bb/NT-004-1.pdf | M9: =IF(K9="","",IF(COUNTIF(I_RegisterBukti!$C$5:$C$130,K9)>1,"DUPLIKAT","Unik")) -> Unik | N9: =IF(D9="","",IF(C9="","TANGGAL KOSONG",IF(AND(C9>=Identitas!$B$32,C9<=Identitas!$B$33),"Sesuai","DI LUAR PERIODE"))) -> Sesuai
A10: 5 | B10: =IF(D10="","",Identitas!$B$6&"-"&TEXT(Identitas!$B$15,"yyyymmdd")&"-BB-"&TEXT(A10,"000")) -> 18.71.XX.XXXX-20261005-BB-005 | C10: 46299 | D10: Buncis | E10: Sayuran | F10: 60 | G10: kg | H10: 15000 | I10: =IF(OR(F10="",H10=""),0,F10*H10) -> 900000 | J10: Pemasok D | K10: NT-004/2 | L10: https://cloud-sipgn.contoh/lpdh/bb/NT-004-2.pdf | M10: =IF(K10="","",IF(COUNTIF(I_RegisterBukti!$C$5:$C$130,K10)>1,"DUPLIKAT","Unik")) -> Unik | N10: =IF(D10="","",IF(C10="","TANGGAL KOSONG",IF(AND(C10>=Identitas!$B$32,C10<=Identitas!$B$33),"Sesuai","DI LUAR PERIODE"))) -> Sesuai
A11: 6 | B11: =IF(D11="","",Identitas!$B$6&"-"&TEXT(Identitas!$B$15,"yyyymmdd")&"-BB-"&TEXT(A11,"000")) -> 18.71.XX.XXXX-20261005-BB-006 | C11: 46299 | D11: Pisang | E11: Buah | F11: 2450 | G11: buah | H11: 1500 | I11: =IF(OR(F11="",H11=""),0,F11*H11) -> 3675000 | J11: Pemasok E | K11: NT-005 | L11: https://cloud-sipgn.contoh/lpdh/bb/NT-005.pdf | M11: =IF(K11="","",IF(COUNTIF(I_RegisterBukti!$C$5:$C$130,K11)>1,"DUPLIKAT","Unik")) -> Unik | N11: =IF(D11="","",IF(C11="","TANGGAL KOSONG",IF(AND(C11>=Identitas!$B$32,C11<=Identitas!$B$33),"Sesuai","DI LUAR PERIODE"))) -> Sesuai
A12: 7 | B12: =IF(D12="","",Identitas!$B$6&"-"&TEXT(Identitas!$B$15,"yyyymmdd")&"-BB-"&TEXT(A12,"000")) -> 18.71.XX.XXXX-20261005-BB-007 | C12: 46299 | D12: Minyak goreng | E12: Minyak dan bumbu | F12: 30 | G12: liter | H12: 18000 | I12: =IF(OR(F12="",H12=""),0,F12*H12) -> 540000 | J12: Pemasok F | K12: NT-006/1 | L12: https://cloud-sipgn.contoh/lpdh/bb/NT-006-1.pdf | M12: =IF(K12="","",IF(COUNTIF(I_RegisterBukti!$C$5:$C$130,K12)>1,"DUPLIKAT","Unik")) -> Unik | N12: =IF(D12="","",IF(C12="","TANGGAL KOSONG",IF(AND(C12>=Identitas!$B$32,C12<=Identitas!$B$33),"Sesuai","DI LUAR PERIODE"))) -> Sesuai
A13: 8 | B13: =IF(D13="","",Identitas!$B$6&"-"&TEXT(Identitas!$B$15,"yyyymmdd")&"-BB-"&TEXT(A13,"000")) -> 18.71.XX.XXXX-20261005-BB-008 | C13: 46299 | D13: Bumbu dapur | E13: Minyak dan bumbu | F13: 1 | G13: paket | H13: 750000 | I13: =IF(OR(F13="",H13=""),0,F13*H13) -> 750000 | J13: Pemasok F | K13: NT-006/2 | L13: https://cloud-sipgn.contoh/lpdh/bb/NT-006-2.pdf | M13: =IF(K13="","",IF(COUNTIF(I_RegisterBukti!$C$5:$C$130,K13)>1,"DUPLIKAT","Unik")) -> Unik | N13: =IF(D13="","",IF(C13="","TANGGAL KOSONG",IF(AND(C13>=Identitas!$B$32,C13<=Identitas!$B$33),"Sesuai","DI LUAR PERIODE"))) -> Sesuai
A14: 9 | B14: =IF(D14="","",Identitas!$B$6&"-"&TEXT(Identitas!$B$15,"yyyymmdd")&"-BB-"&TEXT(A14,"000")) | I14: =IF(OR(F14="",H14=""),0,F14*H14) -> 0 | M14: =IF(K14="","",IF(COUNTIF(I_RegisterBukti!$C$5:$C$130,K14)>1,"DUPLIKAT","Unik")) | N14: =IF(D14="","",IF(C14="","TANGGAL KOSONG",IF(AND(C14>=Identitas!$B$32,C14<=Identitas!$B$33),"Sesuai","DI LUAR PERIODE")))
A15: 10 | B15: =IF(D15="","",Identitas!$B$6&"-"&TEXT(Identitas!$B$15,"yyyymmdd")&"-BB-"&TEXT(A15,"000")) | I15: =IF(OR(F15="",H15=""),0,F15*H15) -> 0 | M15: =IF(K15="","",IF(COUNTIF(I_RegisterBukti!$C$5:$C$130,K15)>1,"DUPLIKAT","Unik")) | N15: =IF(D15="","",IF(C15="","TANGGAL KOSONG",IF(AND(C15>=Identitas!$B$32,C15<=Identitas!$B$33),"Sesuai","DI LUAR PERIODE")))
A16: 11 | B16: =IF(D16="","",Identitas!$B$6&"-"&TEXT(Identitas!$B$15,"yyyymmdd")&"-BB-"&TEXT(A16,"000")) | I16: =IF(OR(F16="",H16=""),0,F16*H16) -> 0 | M16: =IF(K16="","",IF(COUNTIF(I_RegisterBukti!$C$5:$C$130,K16)>1,"DUPLIKAT","Unik")) | N16: =IF(D16="","",IF(C16="","TANGGAL KOSONG",IF(AND(C16>=Identitas!$B$32,C16<=Identitas!$B$33),"Sesuai","DI LUAR PERIODE")))
A17: 12 | B17: =IF(D17="","",Identitas!$B$6&"-"&TEXT(Identitas!$B$15,"yyyymmdd")&"-BB-"&TEXT(A17,"000")) | I17: =IF(OR(F17="",H17=""),0,F17*H17) -> 0 | M17: =IF(K17="","",IF(COUNTIF(I_RegisterBukti!$C$5:$C$130,K17)>1,"DUPLIKAT","Unik")) | N17: =IF(D17="","",IF(C17="","TANGGAL KOSONG",IF(AND(C17>=Identitas!$B$32,C17<=Identitas!$B$33),"Sesuai","DI LUAR PERIODE")))
A18: 13 | B18: =IF(D18="","",Identitas!$B$6&"-"&TEXT(Identitas!$B$15,"yyyymmdd")&"-BB-"&TEXT(A18,"000")) | I18: =IF(OR(F18="",H18=""),0,F18*H18) -> 0 | M18: =IF(K18="","",IF(COUNTIF(I_RegisterBukti!$C$5:$C$130,K18)>1,"DUPLIKAT","Unik")) | N18: =IF(D18="","",IF(C18="","TANGGAL KOSONG",IF(AND(C18>=Identitas!$B$32,C18<=Identitas!$B$33),"Sesuai","DI LUAR PERIODE")))
A19: 14 | B19: =IF(D19="","",Identitas!$B$6&"-"&TEXT(Identitas!$B$15,"yyyymmdd")&"-BB-"&TEXT(A19,"000")) | I19: =IF(OR(F19="",H19=""),0,F19*H19) -> 0 | M19: =IF(K19="","",IF(COUNTIF(I_RegisterBukti!$C$5:$C$130,K19)>1,"DUPLIKAT","Unik")) | N19: =IF(D19="","",IF(C19="","TANGGAL KOSONG",IF(AND(C19>=Identitas!$B$32,C19<=Identitas!$B$33),"Sesuai","DI LUAR PERIODE")))
A20: 15 | B20: =IF(D20="","",Identitas!$B$6&"-"&TEXT(Identitas!$B$15,"yyyymmdd")&"-BB-"&TEXT(A20,"000")) | I20: =IF(OR(F20="",H20=""),0,F20*H20) -> 0 | M20: =IF(K20="","",IF(COUNTIF(I_RegisterBukti!$C$5:$C$130,K20)>1,"DUPLIKAT","Unik")) | N20: =IF(D20="","",IF(C20="","TANGGAL KOSONG",IF(AND(C20>=Identitas!$B$32,C20<=Identitas!$B$33),"Sesuai","DI LUAR PERIODE")))
A21: 16 | B21: =IF(D21="","",Identitas!$B$6&"-"&TEXT(Identitas!$B$15,"yyyymmdd")&"-BB-"&TEXT(A21,"000")) | I21: =IF(OR(F21="",H21=""),0,F21*H21) -> 0 | M21: =IF(K21="","",IF(COUNTIF(I_RegisterBukti!$C$5:$C$130,K21)>1,"DUPLIKAT","Unik")) | N21: =IF(D21="","",IF(C21="","TANGGAL KOSONG",IF(AND(C21>=Identitas!$B$32,C21<=Identitas!$B$33),"Sesuai","DI LUAR PERIODE")))
A22: 17 | B22: =IF(D22="","",Identitas!$B$6&"-"&TEXT(Identitas!$B$15,"yyyymmdd")&"-BB-"&TEXT(A22,"000")) | I22: =IF(OR(F22="",H22=""),0,F22*H22) -> 0 | M22: =IF(K22="","",IF(COUNTIF(I_RegisterBukti!$C$5:$C$130,K22)>1,"DUPLIKAT","Unik")) | N22: =IF(D22="","",IF(C22="","TANGGAL KOSONG",IF(AND(C22>=Identitas!$B$32,C22<=Identitas!$B$33),"Sesuai","DI LUAR PERIODE")))
A23: 18 | B23: =IF(D23="","",Identitas!$B$6&"-"&TEXT(Identitas!$B$15,"yyyymmdd")&"-BB-"&TEXT(A23,"000")) | I23: =IF(OR(F23="",H23=""),0,F23*H23) -> 0 | M23: =IF(K23="","",IF(COUNTIF(I_RegisterBukti!$C$5:$C$130,K23)>1,"DUPLIKAT","Unik")) | N23: =IF(D23="","",IF(C23="","TANGGAL KOSONG",IF(AND(C23>=Identitas!$B$32,C23<=Identitas!$B$33),"Sesuai","DI LUAR PERIODE")))
A24: 19 | B24: =IF(D24="","",Identitas!$B$6&"-"&TEXT(Identitas!$B$15,"yyyymmdd")&"-BB-"&TEXT(A24,"000")) | I24: =IF(OR(F24="",H24=""),0,F24*H24) -> 0 | M24: =IF(K24="","",IF(COUNTIF(I_RegisterBukti!$C$5:$C$130,K24)>1,"DUPLIKAT","Unik")) | N24: =IF(D24="","",IF(C24="","TANGGAL KOSONG",IF(AND(C24>=Identitas!$B$32,C24<=Identitas!$B$33),"Sesuai","DI LUAR PERIODE")))
A25: 20 | B25: =IF(D25="","",Identitas!$B$6&"-"&TEXT(Identitas!$B$15,"yyyymmdd")&"-BB-"&TEXT(A25,"000")) | I25: =IF(OR(F25="",H25=""),0,F25*H25) -> 0 | M25: =IF(K25="","",IF(COUNTIF(I_RegisterBukti!$C$5:$C$130,K25)>1,"DUPLIKAT","Unik")) | N25: =IF(D25="","",IF(C25="","TANGGAL KOSONG",IF(AND(C25>=Identitas!$B$32,C25<=Identitas!$B$33),"Sesuai","DI LUAR PERIODE")))
... A45: 40 | B45: =IF(D45="","",Identitas!$B$6&"-"&TEXT(Identitas!$B$15,"yyyymmdd")&"-BB-"&TEXT(A45,"000")) | I45: =IF(OR(F45="",H45=""),0,F45*H45) -> 0 | M45: =IF(K45="","",IF(COUNTIF(I_RegisterBukti!$C$5:$C$130,K45)>1,"DUPLIKAT","Unik")) | N45: =IF(D45="","",IF(C45="","TANGGAL KOSONG",IF(AND(C45>=Identitas!$B$32,C45<=Identitas!$B$33),"Sesuai","DI LUAR PERIODE")))
A46: TOTAL BELANJA BAHAN BAKU | I46: =SUM(I6:I45) -> 18885000
A48: Indikator | I48: Nilai
A49: Porsi diproduksi (A_PM, Aplikasi POP) | I49: =A_PM!C19 -> 2400
A50: Rata-rata biaya bahan per porsi (Rp) | I50: =IF(I49>0,I46/I49,0) -> 7868.75
A51: Pagu bahan tertimbang setelah indeks kemahalan (Rp) | I51: =A_PM!Q16 -> 9569.6203
A52: Status terhadap pagu | I52: =IF(I50<=I51,"Dalam pagu","Melebihi pagu: jelaskan") -> Dalam pagu

Sheet C_Operasional
A1: C. RINCIAN BIAYA OPERASIONAL (AT COST)
A2: Setiap baris = satu transaksi dengan nomor bukti unik dan link bukti autentik. Insentif relawan dirinci pada lembar C1_Relawan.
A5: No | B5: Kode Unik Transaksi (otomatis) | C5: Tanggal Transaksi | D5: Uraian | E5: Volume | F5: Satuan | G5: Harga Satuan (Rp) | H5: Jumlah (Rp) | I5: No. Bukti | J5: Link Bukti Autentik (Cloud SIPGN) | K5: Status Nomor Bukti | L5: Status Tanggal | M5: Keterangan
A6: 1 | B6: Lihat C1_Relawan | C6: =IF(H6>0,Identitas!B15,"") -> 46300 | D6: Insentif relawan (daftar nominatif C1_Relawan) | E6: ='C1_Relawan'!C66 -> 47 | F6: orang | H6: ='C1_Relawan'!H66 -> 4230000 | I6: Per orang di C1_Relawan | J6: Per orang di C1_Relawan | K6: =IF(COUNTIF('C1_Relawan'!L6:L65,"DUPLIKAT")>0,"DUPLIKAT","Lihat C1") -> Lihat C1 | L6: =IF(COUNTIF('C1_Relawan'!M6:M65,"DI LUAR PERIODE")>0,"DI LUAR PERIODE","Lihat C1") -> Lihat C1
A7: 2 | B7: =IF(I7="","",Identitas!$B$6&"-"&TEXT(Identitas!$B$15,"yyyymmdd")&"-OP-"&TEXT(A7,"000")) -> 18.71.XX.XXXX-20261005-OP-002 | C7: 46300 | D7: Insentif penanggung jawab satuan pendidikan | E7: 4 | F7: satuan | G7: 100000 | H7: =IF(OR(E7="",G7=""),0,E7*G7) -> 400000 | I7: KW-OP-002 | J7: https://cloud-sipgn.contoh/lpdh/op/KW-OP-002.pdf | K7: =IF(I7="","",IF(COUNTIF(I_RegisterBukti!$C$5:$C$130,I7)>1,"DUPLIKAT","Unik")) -> Unik | L7: =IF(I7="","",IF(C7="","TANGGAL KOSONG",IF(AND(C7>=Identitas!$B$32,C7<=Identitas!$B$33),"Sesuai","DI LUAR PERIODE"))) -> Sesuai
A8: 3 | B8: =IF(I8="","",Identitas!$B$6&"-"&TEXT(Identitas!$B$15,"yyyymmdd")&"-OP-"&TEXT(A8,"000")) -> 18.71.XX.XXXX-20261005-OP-003 | C8: 46300 | D8: Insentif kader posyandu | E8: 3 | F8: orang | G8: 50000 | H8: =IF(OR(E8="",G8=""),0,E8*G8) -> 150000 | I8: KW-OP-003 | J8: https://cloud-sipgn.contoh/lpdh/op/KW-OP-003.pdf | K8: =IF(I8="","",IF(COUNTIF(I_RegisterBukti!$C$5:$C$130,I8)>1,"DUPLIKAT","Unik")) -> Unik | L8: =IF(I8="","",IF(C8="","TANGGAL KOSONG",IF(AND(C8>=Identitas!$B$32,C8<=Identitas!$B$33),"Sesuai","DI LUAR PERIODE"))) -> Sesuai
A9: 4 | B9: =IF(I9="","",Identitas!$B$6&"-"&TEXT(Identitas!$B$15,"yyyymmdd")&"-OP-"&TEXT(A9,"000")) | D9: BPJS Ketenagakerjaan | H9: =IF(OR(E9="",G9=""),0,E9*G9) -> 0 | K9: =IF(I9="","",IF(COUNTIF(I_RegisterBukti!$C$5:$C$130,I9)>1,"DUPLIKAT","Unik")) | L9: =IF(I9="","",IF(C9="","TANGGAL KOSONG",IF(AND(C9>=Identitas!$B$32,C9<=Identitas!$B$33),"Sesuai","DI LUAR PERIODE")))
A10: 5 | B10: =IF(I10="","",Identitas!$B$6&"-"&TEXT(Identitas!$B$15,"yyyymmdd")&"-OP-"&TEXT(A10,"000")) -> 18.71.XX.XXXX-20261005-OP-005 | C10: 46300 | D10: Listrik | E10: 1 | F10: hari | G10: 350000 | H10: =IF(OR(E10="",G10=""),0,E10*G10) -> 350000 | I10: KW-OP-005 | J10: https://cloud-sipgn.contoh/lpdh/op/KW-OP-005.pdf | K10: =IF(I10="","",IF(COUNTIF(I_RegisterBukti!$C$5:$C$130,I10)>1,"DUPLIKAT","Unik")) -> Unik | L10: =IF(I10="","",IF(C10="","TANGGAL KOSONG",IF(AND(C10>=Identitas!$B$32,C10<=Identitas!$B$33),"Sesuai","DI LUAR PERIODE"))) -> Sesuai
A11: 6 | B11: =IF(I11="","",Identitas!$B$6&"-"&TEXT(Identitas!$B$15,"yyyymmdd")&"-OP-"&TEXT(A11,"000")) -> 18.71.XX.XXXX-20261005-OP-006 | C11: 46300 | D11: Air PDAM | E11: 1 | F11: hari | G11: 60000 | H11: =IF(OR(E11="",G11=""),0,E11*G11) -> 60000 | I11: KW-OP-006 | J11: https://cloud-sipgn.contoh/lpdh/op/KW-OP-006.pdf | K11: =IF(I11="","",IF(COUNTIF(I_RegisterBukti!$C$5:$C$130,I11)>1,"DUPLIKAT","Unik")) -> Unik | L11: =IF(I11="","",IF(C11="","TANGGAL KOSONG",IF(AND(C11>=Identitas!$B$32,C11<=Identitas!$B$33),"Sesuai","DI LUAR PERIODE"))) -> Sesuai
A12: 7 | B12: =IF(I12="","",Identitas!$B$6&"-"&TEXT(Identitas!$B$15,"yyyymmdd")&"-OP-"&TEXT(A12,"000")) -> 18.71.XX.XXXX-20261005-OP-007 | C12: 46300 | D12: Air minum/galon | E12: 10 | F12: galon | G12: 6000 | H12: =IF(OR(E12="",G12=""),0,E12*G12) -> 60000 | I12: KW-OP-007 | J12: https://cloud-sipgn.contoh/lpdh/op/KW-OP-007.pdf | K12: =IF(I12="","",IF(COUNTIF(I_RegisterBukti!$C$5:$C$130,I12)>1,"DUPLIKAT","Unik")) -> Unik | L12: =IF(I12="","",IF(C12="","TANGGAL KOSONG",IF(AND(C12>=Identitas!$B$32,C12<=Identitas!$B$33),"Sesuai","DI LUAR PERIODE"))) -> Sesuai
A13: 8 | B13: =IF(I13="","",Identitas!$B$6&"-"&TEXT(Identitas!$B$15,"yyyymmdd")&"-OP-"&TEXT(A13,"000")) -> 18.71.XX.XXXX-20261005-OP-008 | C13: 46300 | D13: Gas | E13: 4 | F13: tabung | G13: 230000 | H13: =IF(OR(E13="",G13=""),0,E13*G13) -> 920000 | I13: KW-OP-008 | J13: https://cloud-sipgn.contoh/lpdh/op/KW-OP-008.pdf | K13: =IF(I13="","",IF(COUNTIF(I_RegisterBukti!$C$5:$C$130,I13)>1,"DUPLIKAT","Unik")) -> Unik | L13: =IF(I13="","",IF(C13="","TANGGAL KOSONG",IF(AND(C13>=Identitas!$B$32,C13<=Identitas!$B$33),"Sesuai","DI LUAR PERIODE"))) -> Sesuai
A14: 9 | B14: =IF(I14="","",Identitas!$B$6&"-"&TEXT(Identitas!$B$15,"yyyymmdd")&"-OP-"&TEXT(A14,"000")) | D14: Sewa kendaraan | H14: =IF(OR(E14="",G14=""),0,E14*G14) -> 0 | K14: =IF(I14="","",IF(COUNTIF(I_RegisterBukti!$C$5:$C$130,I14)>1,"DUPLIKAT","Unik")) | L14: =IF(I14="","",IF(C14="","TANGGAL KOSONG",IF(AND(C14>=Identitas!$B$32,C14<=Identitas!$B$33),"Sesuai","DI LUAR PERIODE")))
A15: 10 | B15: =IF(I15="","",Identitas!$B$6&"-"&TEXT(Identitas!$B$15,"yyyymmdd")&"-OP-"&TEXT(A15,"000")) -> 18.71.XX.XXXX-20261005-OP-010 | C15: 46300 | D15: BBM | E15: 40 | F15: liter | G15: 10000 | H15: =IF(OR(E15="",G15=""),0,E15*G15) -> 400000 | I15: KW-OP-010 | J15: https://cloud-sipgn.contoh/lpdh/op/KW-OP-010.pdf | K15: =IF(I15="","",IF(COUNTIF(I_RegisterBukti!$C$5:$C$130,I15)>1,"DUPLIKAT","Unik")) -> Unik | L15: =IF(I15="","",IF(C15="","TANGGAL KOSONG",IF(AND(C15>=Identitas!$B$32,C15<=Identitas!$B$33),"Sesuai","DI LUAR PERIODE"))) -> Sesuai
A16: 11 | B16: =IF(I16="","",Identitas!$B$6&"-"&TEXT(Identitas!$B$15,"yyyymmdd")&"-OP-"&TEXT(A16,"000")) -> 18.71.XX.XXXX-20261005-OP-011 | C16: 46300 | D16: Pulsa dan internet | E16: 1 | F16: hari | G16: 25000 | H16: =IF(OR(E16="",G16=""),0,E16*G16) -> 25000 | I16: KW-OP-011 | J16: https://cloud-sipgn.contoh/lpdh/op/KW-OP-011.pdf | K16: =IF(I16="","",IF(COUNTIF(I_RegisterBukti!$C$5:$C$130,I16)>1,"DUPLIKAT","Unik")) -> Unik | L16: =IF(I16="","",IF(C16="","TANGGAL KOSONG",IF(AND(C16>=Identitas!$B$32,C16<=Identitas!$B$33),"Sesuai","DI LUAR PERIODE"))) -> Sesuai
A17: 12 | B17: =IF(I17="","",Identitas!$B$6&"-"&TEXT(Identitas!$B$15,"yyyymmdd")&"-OP-"&TEXT(A17,"000")) | D17: ATK | H17: =IF(OR(E17="",G17=""),0,E17*G17) -> 0 | K17: =IF(I17="","",IF(COUNTIF(I_RegisterBukti!$C$5:$C$130,I17)>1,"DUPLIKAT","Unik")) | L17: =IF(I17="","",IF(C17="","TANGGAL KOSONG",IF(AND(C17>=Identitas!$B$32,C17<=Identitas!$B$33),"Sesuai","DI LUAR PERIODE")))
A18: 13 | B18: =IF(I18="","",Identitas!$B$6&"-"&TEXT(Identitas!$B$15,"yyyymmdd")&"-OP-"&TEXT(A18,"000")) -> 18.71.XX.XXXX-20261005-OP-013 | C18: 46300 | D18: Alat kebersihan | E18: 1 | F18: paket | G18: 75000 | H18: =IF(OR(E18="",G18=""),0,E18*G18) -> 75000 | I18: KW-OP-013 | J18: https://cloud-sipgn.contoh/lpdh/op/KW-OP-013.pdf | K18: =IF(I18="","",IF(COUNTIF(I_RegisterBukti!$C$5:$C$130,I18)>1,"DUPLIKAT","Unik")) -> Unik | L18: =IF(I18="","",IF(C18="","TANGGAL KOSONG",IF(AND(C18>=Identitas!$B$32,C18<=Identitas!$B$33),"Sesuai","DI LUAR PERIODE"))) -> Sesuai
A19: 14 | B19: =IF(I19="","",Identitas!$B$6&"-"&TEXT(Identitas!$B$15,"yyyymmdd")&"-OP-"&TEXT(A19,"000")) -> 18.71.XX.XXXX-20261005-OP-014 | C19: 46300 | D19: APD (masker, sarung tangan, penutup kepala) | E19: 1 | F19: paket | G19: 120000 | H19: =IF(OR(E19="",G19=""),0,E19*G19) -> 120000 | I19: KW-OP-014 | J19: https://cloud-sipgn.contoh/lpdh/op/KW-OP-014.pdf | K19: =IF(I19="","",IF(COUNTIF(I_RegisterBukti!$C$5:$C$130,I19)>1,"DUPLIKAT","Unik")) -> Unik | L19: =IF(I19="","",IF(C19="","TANGGAL KOSONG",IF(AND(C19>=Identitas!$B$32,C19<=Identitas!$B$33),"Sesuai","DI LUAR PERIODE"))) -> Sesuai
A20: 15 | B20: =IF(I20="","",Identitas!$B$6&"-"&TEXT(Identitas!$B$15,"yyyymmdd")&"-OP-"&TEXT(A20,"000")) | D20: Biaya rapat koordinasi | H20: =IF(OR(E20="",G20=""),0,E20*G20) -> 0 | K20: =IF(I20="","",IF(COUNTIF(I_RegisterBukti!$C$5:$C$130,I20)>1,"DUPLIKAT","Unik")) | L20: =IF(I20="","",IF(C20="","TANGGAL KOSONG",IF(AND(C20>=Identitas!$B$32,C20<=Identitas!$B$33),"Sesuai","DI LUAR PERIODE")))
A21: 16 | B21: =IF(I21="","",Identitas!$B$6&"-"&TEXT(Identitas!$B$15,"yyyymmdd")&"-OP-"&TEXT(A21,"000")) | D21: Lain-lain | H21: =IF(OR(E21="",G21=""),0,E21*G21) -> 0 | K21: =IF(I21="","",IF(COUNTIF(I_RegisterBukti!$C$5:$C$130,I21)>1,"DUPLIKAT","Unik")) | L21: =IF(I21="","",IF(C21="","TANGGAL KOSONG",IF(AND(C21>=Identitas!$B$32,C21<=Identitas!$B$33),"Sesuai","DI LUAR PERIODE")))
A22: TOTAL BIAYA OPERASIONAL | H22: =SUM(H6:H21) -> 6790000
A24: Indikator | H24: Nilai
A25: PM dihitung (A_PM) | H25: =A_PM!C47 -> 2339
A26: Biaya operasional per PM (Rp) | H26: =IF(H25>0,H22/H25,0) -> 2902.95
A27: Pagu operasional per PM setelah indeks kemahalan (Rp) | H27: =Ref!B8*IF(Ref!B15="Ya",Identitas!B21,1) -> 3150
A28: Status terhadap pagu | H28: =IF(H26<=H27,"Dalam pagu","Melebihi pagu: jelaskan") -> Dalam pagu

Sheet C1_Relawan
A1: C.1 DAFTAR NOMINATIF PEMBAYARAN INSENTIF RELAWAN
A2: Setiap pembayaran wajib memiliki nomor bukti pembayaran unik dan link bukti autentik (kuitansi/bukti transfer). Total otomatis masuk ke C_Operasional.
A5: No | B5: Kode Unik Transaksi (otomatis) | C5: Nama Relawan | D5: Tugas | E5: Tanggal Pembayaran | F5: Hari Kerja | G5: Besaran Harian (Rp) | H5: Jumlah Diterima (Rp) | I5: Metode Bayar | J5: No. Bukti Pembayaran | K5: Link Bukti Bayar (Cloud SIPGN) | L5: Status Nomor Bukti | M5: Status Tanggal | N5: Status Bukti
A6: 1 | B6: =IF(C6="","",Identitas!$B$6&"-"&TEXT(Identitas!$B$15,"yyyymmdd")&"-RL-"&TEXT(A6,"000")) -> 18.71.XX.XXXX-20261005-RL-001 | C6: Relawan 01 | D6: Juru masak | E6: 46300 | F6: 1 | G6: 90000 | H6: =IF(OR(F6="",G6=""),0,F6*G6) -> 90000 | I6: Transfer | J6: BYR-RL-001 | K6: https://cloud-sipgn.contoh/lpdh/relawan/BYR-RL-001.pdf | L6: =IF(J6="","",IF(COUNTIF(I_RegisterBukti!$C$5:$C$130,J6)>1,"DUPLIKAT","Unik")) -> Unik | M6: =IF(C6="","",IF(E6="","TANGGAL KOSONG",IF(AND(E6>=Identitas!$B$32,E6<=Identitas!$B$33),"Sesuai","DI LUAR PERIODE"))) -> Sesuai | N6: =IF(N(H6)=0,"",IF(AND(J6<>"",LEFT(K6,8)="https://"),"Lengkap","BELUM LENGKAP")) -> Lengkap
A7: 2 | B7: =IF(C7="","",Identitas!$B$6&"-"&TEXT(Identitas!$B$15,"yyyymmdd")&"-RL-"&TEXT(A7,"000")) -> 18.71.XX.XXXX-20261005-RL-002 | C7: Relawan 02 | D7: Juru masak | E7: 46300 | F7: 1 | G7: 90000 | H7: =IF(OR(F7="",G7=""),0,F7*G7) -> 90000 | I7: Transfer | J7: BYR-RL-002 | K7: https://cloud-sipgn.contoh/lpdh/relawan/BYR-RL-002.pdf | L7: =IF(J7="","",IF(COUNTIF(I_RegisterBukti!$C$5:$C$130,J7)>1,"DUPLIKAT","Unik")) -> Unik | M7: =IF(C7="","",IF(E7="","TANGGAL KOSONG",IF(AND(E7>=Identitas!$B$32,E7<=Identitas!$B$33),"Sesuai","DI LUAR PERIODE"))) -> Sesuai | N7: =IF(N(H7)=0,"",IF(AND(J7<>"",LEFT(K7,8)="https://"),"Lengkap","BELUM LENGKAP")) -> Lengkap
A8: 3 | B8: =IF(C8="","",Identitas!$B$6&"-"&TEXT(Identitas!$B$15,"yyyymmdd")&"-RL-"&TEXT(A8,"000")) -> 18.71.XX.XXXX-20261005-RL-003 | C8: Relawan 03 | D8: Juru masak | E8: 46300 | F8: 1 | G8: 90000 | H8: =IF(OR(F8="",G8=""),0,F8*G8) -> 90000 | I8: Transfer | J8: BYR-RL-003 | K8: https://cloud-sipgn.contoh/lpdh/relawan/BYR-RL-003.pdf | L8: =IF(J8="","",IF(COUNTIF(I_RegisterBukti!$C$5:$C$130,J8)>1,"DUPLIKAT","Unik")) -> Unik | M8: =IF(C8="","",IF(E8="","TANGGAL KOSONG",IF(AND(E8>=Identitas!$B$32,E8<=Identitas!$B$33),"Sesuai","DI LUAR PERIODE"))) -> Sesuai | N8: =IF(N(H8)=0,"",IF(AND(J8<>"",LEFT(K8,8)="https://"),"Lengkap","BELUM LENGKAP")) -> Lengkap
A9: 4 | B9: =IF(C9="","",Identitas!$B$6&"-"&TEXT(Identitas!$B$15,"yyyymmdd")&"-RL-"&TEXT(A9,"000")) -> 18.71.XX.XXXX-20261005-RL-004 | C9: Relawan 04 | D9: Juru masak | E9: 46300 | F9: 1 | G9: 90000 | H9: =IF(OR(F9="",G9=""),0,F9*G9) -> 90000 | I9: Transfer | J9: BYR-RL-004 | K9: https://cloud-sipgn.contoh/lpdh/relawan/BYR-RL-004.pdf | L9: =IF(J9="","",IF(COUNTIF(I_RegisterBukti!$C$5:$C$130,J9)>1,"DUPLIKAT","Unik")) -> Unik | M9: =IF(C9="","",IF(E9="","TANGGAL KOSONG",IF(AND(E9>=Identitas!$B$32,E9<=Identitas!$B$33),"Sesuai","DI LUAR PERIODE"))) -> Sesuai | N9: =IF(N(H9)=0,"",IF(AND(J9<>"",LEFT(K9,8)="https://"),"Lengkap","BELUM LENGKAP")) -> Lengkap
A10: 5 | B10: =IF(C10="","",Identitas!$B$6&"-"&TEXT(Identitas!$B$15,"yyyymmdd")&"-RL-"&TEXT(A10,"000")) -> 18.71.XX.XXXX-20261005-RL-005 | C10: Relawan 05 | D10: Juru masak | E10: 46300 | F10: 1 | G10: 90000 | H10: =IF(OR(F10="",G10=""),0,F10*G10) -> 90000 | I10: Transfer | J10: BYR-RL-005 | K10: https://cloud-sipgn.contoh/lpdh/relawan/BYR-RL-005.pdf | L10: =IF(J10="","",IF(COUNTIF(I_RegisterBukti!$C$5:$C$130,J10)>1,"DUPLIKAT","Unik")) -> Unik | M10: =IF(C10="","",IF(E10="","TANGGAL KOSONG",IF(AND(E10>=Identitas!$B$32,E10<=Identitas!$B$33),"Sesuai","DI LUAR PERIODE"))) -> Sesuai | N10: =IF(N(H10)=0,"",IF(AND(J10<>"",LEFT(K10,8)="https://"),"Lengkap","BELUM LENGKAP")) -> Lengkap
A11: 6 | B11: =IF(C11="","",Identitas!$B$6&"-"&TEXT(Identitas!$B$15,"yyyymmdd")&"-RL-"&TEXT(A11,"000")) -> 18.71.XX.XXXX-20261005-RL-006 | C11: Relawan 06 | D11: Juru masak | E11: 46300 | F11: 1 | G11: 90000 | H11: =IF(OR(F11="",G11=""),0,F11*G11) -> 90000 | I11: Transfer | J11: BYR-RL-006 | K11: https://cloud-sipgn.contoh/lpdh/relawan/BYR-RL-006.pdf | L11: =IF(J11="","",IF(COUNTIF(I_RegisterBukti!$C$5:$C$130,J11)>1,"DUPLIKAT","Unik")) -> Unik | M11: =IF(C11="","",IF(E11="","TANGGAL KOSONG",IF(AND(E11>=Identitas!$B$32,E11<=Identitas!$B$33),"Sesuai","DI LUAR PERIODE"))) -> Sesuai | N11: =IF(N(H11)=0,"",IF(AND(J11<>"",LEFT(K11,8)="https://"),"Lengkap","BELUM LENGKAP")) -> Lengkap
A12: 7 | B12: =IF(C12="","",Identitas!$B$6&"-"&TEXT(Identitas!$B$15,"yyyymmdd")&"-RL-"&TEXT(A12,"000")) -> 18.71.XX.XXXX-20261005-RL-007 | C12: Relawan 07 | D12: Juru masak | E12: 46300 | F12: 1 | G12: 90000 | H12: =IF(OR(F12="",G12=""),0,F12*G12) -> 90000 | I12: Transfer | J12: BYR-RL-007 | K12: https://cloud-sipgn.contoh/lpdh/relawan/BYR-RL-007.pdf | L12: =IF(J12="","",IF(COUNTIF(I_RegisterBukti!$C$5:$C$130,J12)>1,"DUPLIKAT","Unik")) -> Unik | M12: =IF(C12="","",IF(E12="","TANGGAL KOSONG",IF(AND(E12>=Identitas!$B$32,E12<=Identitas!$B$33),"Sesuai","DI LUAR PERIODE"))) -> Sesuai | N12: =IF(N(H12)=0,"",IF(AND(J12<>"",LEFT(K12,8)="https://"),"Lengkap","BELUM LENGKAP")) -> Lengkap
A13: 8 | B13: =IF(C13="","",Identitas!$B$6&"-"&TEXT(Identitas!$B$15,"yyyymmdd")&"-RL-"&TEXT(A13,"000")) -> 18.71.XX.XXXX-20261005-RL-008 | C13: Relawan 08 | D13: Juru masak | E13: 46300 | F13: 1 | G13: 90000 | H13: =IF(OR(F13="",G13=""),0,F13*G13) -> 90000 | I13: Transfer | J13: BYR-RL-008 | K13: https://cloud-sipgn.contoh/lpdh/relawan/BYR-RL-008.pdf | L13: =IF(J13="","",IF(COUNTIF(I_RegisterBukti!$C$5:$C$130,J13)>1,"DUPLIKAT","Unik")) -> Unik | M13: =IF(C13="","",IF(E13="","TANGGAL KOSONG",IF(AND(E13>=Identitas!$B$32,E13<=Identitas!$B$33),"Sesuai","DI LUAR PERIODE"))) -> Sesuai | N13: =IF(N(H13)=0,"",IF(AND(J13<>"",LEFT(K13,8)="https://"),"Lengkap","BELUM LENGKAP")) -> Lengkap
A14: 9 | B14: =IF(C14="","",Identitas!$B$6&"-"&TEXT(Identitas!$B$15,"yyyymmdd")&"-RL-"&TEXT(A14,"000")) -> 18.71.XX.XXXX-20261005-RL-009 | C14: Relawan 09 | D14: Juru masak | E14: 46300 | F14: 1 | G14: 90000 | H14: =IF(OR(F14="",G14=""),0,F14*G14) -> 90000 | I14: Transfer | J14: BYR-RL-009 | K14: https://cloud-sipgn.contoh/lpdh/relawan/BYR-RL-009.pdf | L14: =IF(J14="","",IF(COUNTIF(I_RegisterBukti!$C$5:$C$130,J14)>1,"DUPLIKAT","Unik")) -> Unik | M14: =IF(C14="","",IF(E14="","TANGGAL KOSONG",IF(AND(E14>=Identitas!$B$32,E14<=Identitas!$B$33),"Sesuai","DI LUAR PERIODE"))) -> Sesuai | N14: =IF(N(H14)=0,"",IF(AND(J14<>"",LEFT(K14,8)="https://"),"Lengkap","BELUM LENGKAP")) -> Lengkap
A15: 10 | B15: =IF(C15="","",Identitas!$B$6&"-"&TEXT(Identitas!$B$15,"yyyymmdd")&"-RL-"&TEXT(A15,"000")) -> 18.71.XX.XXXX-20261005-RL-010 | C15: Relawan 10 | D15: Juru masak | E15: 46300 | F15: 1 | G15: 90000 | H15: =IF(OR(F15="",G15=""),0,F15*G15) -> 90000 | I15: Transfer | J15: BYR-RL-010 | K15: https://cloud-sipgn.contoh/lpdh/relawan/BYR-RL-010.pdf | L15: =IF(J15="","",IF(COUNTIF(I_RegisterBukti!$C$5:$C$130,J15)>1,"DUPLIKAT","Unik")) -> Unik | M15: =IF(C15="","",IF(E15="","TANGGAL KOSONG",IF(AND(E15>=Identitas!$B$32,E15<=Identitas!$B$33),"Sesuai","DI LUAR PERIODE"))) -> Sesuai | N15: =IF(N(H15)=0,"",IF(AND(J15<>"",LEFT(K15,8)="https://"),"Lengkap","BELUM LENGKAP")) -> Lengkap
A16: 11 | B16: =IF(C16="","",Identitas!$B$6&"-"&TEXT(Identitas!$B$15,"yyyymmdd")&"-RL-"&TEXT(A16,"000")) -> 18.71.XX.XXXX-20261005-RL-011 | C16: Relawan 11 | D16: Juru masak | E16: 46300 | F16: 1 | G16: 90000 | H16: =IF(OR(F16="",G16=""),0,F16*G16) -> 90000 | I16: Transfer | J16: BYR-RL-011 | K16: https://cloud-sipgn.contoh/lpdh/relawan/BYR-RL-011.pdf | L16: =IF(J16="","",IF(COUNTIF(I_RegisterBukti!$C$5:$C$130,J16)>1,"DUPLIKAT","Unik")) -> Unik | M16: =IF(C16="","",IF(E16="","TANGGAL KOSONG",IF(AND(E16>=Identitas!$B$32,E16<=Identitas!$B$33),"Sesuai","DI LUAR PERIODE"))) -> Sesuai | N16: =IF(N(H16)=0,"",IF(AND(J16<>"",LEFT(K16,8)="https://"),"Lengkap","BELUM LENGKAP")) -> Lengkap
A17: 12 | B17: =IF(C17="","",Identitas!$B$6&"-"&TEXT(Identitas!$B$15,"yyyymmdd")&"-RL-"&TEXT(A17,"000")) -> 18.71.XX.XXXX-20261005-RL-012 | C17: Relawan 12 | D17: Juru masak | E17: 46300 | F17: 1 | G17: 90000 | H17: =IF(OR(F17="",G17=""),0,F17*G17) -> 90000 | I17: Transfer | J17: BYR-RL-012 | K17: https://cloud-sipgn.contoh/lpdh/relawan/BYR-RL-012.pdf | L17: =IF(J17="","",IF(COUNTIF(I_RegisterBukti!$C$5:$C$130,J17)>1,"DUPLIKAT","Unik")) -> Unik | M17: =IF(C17="","",IF(E17="","TANGGAL KOSONG",IF(AND(E17>=Identitas!$B$32,E17<=Identitas!$B$33),"Sesuai","DI LUAR PERIODE"))) -> Sesuai | N17: =IF(N(H17)=0,"",IF(AND(J17<>"",LEFT(K17,8)="https://"),"Lengkap","BELUM LENGKAP")) -> Lengkap
... A52: 47 | B52: =IF(C52="","",Identitas!$B$6&"-"&TEXT(Identitas!$B$15,"yyyymmdd")&"-RL-"&TEXT(A52,"000")) -> 18.71.XX.XXXX-20261005-RL-047 | C52: Relawan 47 | D52: Keamanan | E52: 46300 | F52: 1 | G52: 90000 | H52: =IF(OR(F52="",G52=""),0,F52*G52) -> 90000 | I52: Transfer | J52: BYR-RL-047 | K52: https://cloud-sipgn.contoh/lpdh/relawan/BYR-RL-047.pdf | L52: =IF(J52="","",IF(COUNTIF(I_RegisterBukti!$C$5:$C$130,J52)>1,"DUPLIKAT","Unik")) -> Unik | M52: =IF(C52="","",IF(E52="","TANGGAL KOSONG",IF(AND(E52>=Identitas!$B$32,E52<=Identitas!$B$33),"Sesuai","DI LUAR PERIODE"))) -> Sesuai | N52: =IF(N(H52)=0,"",IF(AND(J52<>"",LEFT(K52,8)="https://"),"Lengkap","BELUM LENGKAP")) -> Lengkap
A53: 48 | B53: =IF(C53="","",Identitas!$B$6&"-"&TEXT(Identitas!$B$15,"yyyymmdd")&"-RL-"&TEXT(A53,"000")) | H53: =IF(OR(F53="",G53=""),0,F53*G53) -> 0 | L53: =IF(J53="","",IF(COUNTIF(I_RegisterBukti!$C$5:$C$130,J53)>1,"DUPLIKAT","Unik")) | M53: =IF(C53="","",IF(E53="","TANGGAL KOSONG",IF(AND(E53>=Identitas!$B$32,E53<=Identitas!$B$33),"Sesuai","DI LUAR PERIODE"))) | N53: =IF(N(H53)=0,"",IF(AND(J53<>"",LEFT(K53,8)="https://"),"Lengkap","BELUM LENGKAP"))
A54: 49 | B54: =IF(C54="","",Identitas!$B$6&"-"&TEXT(Identitas!$B$15,"yyyymmdd")&"-RL-"&TEXT(A54,"000")) | H54: =IF(OR(F54="",G54=""),0,F54*G54) -> 0 | L54: =IF(J54="","",IF(COUNTIF(I_RegisterBukti!$C$5:$C$130,J54)>1,"DUPLIKAT","Unik")) | M54: =IF(C54="","",IF(E54="","TANGGAL KOSONG",IF(AND(E54>=Identitas!$B$32,E54<=Identitas!$B$33),"Sesuai","DI LUAR PERIODE"))) | N54: =IF(N(H54)=0,"",IF(AND(J54<>"",LEFT(K54,8)="https://"),"Lengkap","BELUM LENGKAP"))
A55: 50 | B55: =IF(C55="","",Identitas!$B$6&"-"&TEXT(Identitas!$B$15,"yyyymmdd")&"-RL-"&TEXT(A55,"000")) | H55: =IF(OR(F55="",G55=""),0,F55*G55) -> 0 | L55: =IF(J55="","",IF(COUNTIF(I_RegisterBukti!$C$5:$C$130,J55)>1,"DUPLIKAT","Unik")) | M55: =IF(C55="","",IF(E55="","TANGGAL KOSONG",IF(AND(E55>=Identitas!$B$32,E55<=Identitas!$B$33),"Sesuai","DI LUAR PERIODE"))) | N55: =IF(N(H55)=0,"",IF(AND(J55<>"",LEFT(K55,8)="https://"),"Lengkap","BELUM LENGKAP"))
A56: 51 | B56: =IF(C56="","",Identitas!$B$6&"-"&TEXT(Identitas!$B$15,"yyyymmdd")&"-RL-"&TEXT(A56,"000")) | H56: =IF(OR(F56="",G56=""),0,F56*G56) -> 0 | L56: =IF(J56="","",IF(COUNTIF(I_RegisterBukti!$C$5:$C$130,J56)>1,"DUPLIKAT","Unik")) | M56: =IF(C56="","",IF(E56="","TANGGAL KOSONG",IF(AND(E56>=Identitas!$B$32,E56<=Identitas!$B$33),"Sesuai","DI LUAR PERIODE"))) | N56: =IF(N(H56)=0,"",IF(AND(J56<>"",LEFT(K56,8)="https://"),"Lengkap","BELUM LENGKAP"))
A57: 52 | B57: =IF(C57="","",Identitas!$B$6&"-"&TEXT(Identitas!$B$15,"yyyymmdd")&"-RL-"&TEXT(A57,"000")) | H57: =IF(OR(F57="",G57=""),0,F57*G57) -> 0 | L57: =IF(J57="","",IF(COUNTIF(I_RegisterBukti!$C$5:$C$130,J57)>1,"DUPLIKAT","Unik")) | M57: =IF(C57="","",IF(E57="","TANGGAL KOSONG",IF(AND(E57>=Identitas!$B$32,E57<=Identitas!$B$33),"Sesuai","DI LUAR PERIODE"))) | N57: =IF(N(H57)=0,"",IF(AND(J57<>"",LEFT(K57,8)="https://"),"Lengkap","BELUM LENGKAP"))
A58: 53 | B58: =IF(C58="","",Identitas!$B$6&"-"&TEXT(Identitas!$B$15,"yyyymmdd")&"-RL-"&TEXT(A58,"000")) | H58: =IF(OR(F58="",G58=""),0,F58*G58) -> 0 | L58: =IF(J58="","",IF(COUNTIF(I_RegisterBukti!$C$5:$C$130,J58)>1,"DUPLIKAT","Unik")) | M58: =IF(C58="","",IF(E58="","TANGGAL KOSONG",IF(AND(E58>=Identitas!$B$32,E58<=Identitas!$B$33),"Sesuai","DI LUAR PERIODE"))) | N58: =IF(N(H58)=0,"",IF(AND(J58<>"",LEFT(K58,8)="https://"),"Lengkap","BELUM LENGKAP"))
A59: 54 | B59: =IF(C59="","",Identitas!$B$6&"-"&TEXT(Identitas!$B$15,"yyyymmdd")&"-RL-"&TEXT(A59,"000")) | H59: =IF(OR(F59="",G59=""),0,F59*G59) -> 0 | L59: =IF(J59="","",IF(COUNTIF(I_RegisterBukti!$C$5:$C$130,J59)>1,"DUPLIKAT","Unik")) | M59: =IF(C59="","",IF(E59="","TANGGAL KOSONG",IF(AND(E59>=Identitas!$B$32,E59<=Identitas!$B$33),"Sesuai","DI LUAR PERIODE"))) | N59: =IF(N(H59)=0,"",IF(AND(J59<>"",LEFT(K59,8)="https://"),"Lengkap","BELUM LENGKAP"))
A60: 55 | B60: =IF(C60="","",Identitas!$B$6&"-"&TEXT(Identitas!$B$15,"yyyymmdd")&"-RL-"&TEXT(A60,"000")) | H60: =IF(OR(F60="",G60=""),0,F60*G60) -> 0 | L60: =IF(J60="","",IF(COUNTIF(I_RegisterBukti!$C$5:$C$130,J60)>1,"DUPLIKAT","Unik")) | M60: =IF(C60="","",IF(E60="","TANGGAL KOSONG",IF(AND(E60>=Identitas!$B$32,E60<=Identitas!$B$33),"Sesuai","DI LUAR PERIODE"))) | N60: =IF(N(H60)=0,"",IF(AND(J60<>"",LEFT(K60,8)="https://"),"Lengkap","BELUM LENGKAP"))
A61: 56 | B61: =IF(C61="","",Identitas!$B$6&"-"&TEXT(Identitas!$B$15,"yyyymmdd")&"-RL-"&TEXT(A61,"000")) | H61: =IF(OR(F61="",G61=""),0,F61*G61) -> 0 | L61: =IF(J61="","",IF(COUNTIF(I_RegisterBukti!$C$5:$C$130,J61)>1,"DUPLIKAT","Unik")) | M61: =IF(C61="","",IF(E61="","TANGGAL KOSONG",IF(AND(E61>=Identitas!$B$32,E61<=Identitas!$B$33),"Sesuai","DI LUAR PERIODE"))) | N61: =IF(N(H61)=0,"",IF(AND(J61<>"",LEFT(K61,8)="https://"),"Lengkap","BELUM LENGKAP"))
A62: 57 | B62: =IF(C62="","",Identitas!$B$6&"-"&TEXT(Identitas!$B$15,"yyyymmdd")&"-RL-"&TEXT(A62,"000")) | H62: =IF(OR(F62="",G62=""),0,F62*G62) -> 0 | L62: =IF(J62="","",IF(COUNTIF(I_RegisterBukti!$C$5:$C$130,J62)>1,"DUPLIKAT","Unik")) | M62: =IF(C62="","",IF(E62="","TANGGAL KOSONG",IF(AND(E62>=Identitas!$B$32,E62<=Identitas!$B$33),"Sesuai","DI LUAR PERIODE"))) | N62: =IF(N(H62)=0,"",IF(AND(J62<>"",LEFT(K62,8)="https://"),"Lengkap","BELUM LENGKAP"))
A63: 58 | B63: =IF(C63="","",Identitas!$B$6&"-"&TEXT(Identitas!$B$15,"yyyymmdd")&"-RL-"&TEXT(A63,"000")) | H63: =IF(OR(F63="",G63=""),0,F63*G63) -> 0 | L63: =IF(J63="","",IF(COUNTIF(I_RegisterBukti!$C$5:$C$130,J63)>1,"DUPLIKAT","Unik")) | M63: =IF(C63="","",IF(E63="","TANGGAL KOSONG",IF(AND(E63>=Identitas!$B$32,E63<=Identitas!$B$33),"Sesuai","DI LUAR PERIODE"))) | N63: =IF(N(H63)=0,"",IF(AND(J63<>"",LEFT(K63,8)="https://"),"Lengkap","BELUM LENGKAP"))
A64: 59 | B64: =IF(C64="","",Identitas!$B$6&"-"&TEXT(Identitas!$B$15,"yyyymmdd")&"-RL-"&TEXT(A64,"000")) | H64: =IF(OR(F64="",G64=""),0,F64*G64) -> 0 | L64: =IF(J64="","",IF(COUNTIF(I_RegisterBukti!$C$5:$C$130,J64)>1,"DUPLIKAT","Unik")) | M64: =IF(C64="","",IF(E64="","TANGGAL KOSONG",IF(AND(E64>=Identitas!$B$32,E64<=Identitas!$B$33),"Sesuai","DI LUAR PERIODE"))) | N64: =IF(N(H64)=0,"",IF(AND(J64<>"",LEFT(K64,8)="https://"),"Lengkap","BELUM LENGKAP"))
A65: 60 | B65: =IF(C65="","",Identitas!$B$6&"-"&TEXT(Identitas!$B$15,"yyyymmdd")&"-RL-"&TEXT(A65,"000")) | H65: =IF(OR(F65="",G65=""),0,F65*G65) -> 0 | L65: =IF(J65="","",IF(COUNTIF(I_RegisterBukti!$C$5:$C$130,J65)>1,"DUPLIKAT","Unik")) | M65: =IF(C65="","",IF(E65="","TANGGAL KOSONG",IF(AND(E65>=Identitas!$B$32,E65<=Identitas!$B$33),"Sesuai","DI LUAR PERIODE"))) | N65: =IF(N(H65)=0,"",IF(AND(J65<>"",LEFT(K65,8)="https://"),"Lengkap","BELUM LENGKAP"))
A66: JUMLAH | C66: =COUNTIF(H6:H65,">0") -> 47 | H66: =SUM(H6:H65) -> 4230000

Sheet D_Insentif
A1: D. PENGHITUNGAN DAN PEMBAYARAN INSENTIF KETERSEDIAAN DAN MUTU LAYANAN
A2: Insentif = tarif × PM dihitung bila seluruh syarat terpenuhi. Pembayaran harian ke Mitra/Yayasan sesuai pernyataan PPK, dengan bukti autentik.
A4: Syarat Pemberian Insentif | B4: Isian | C4: Syarat Terpenuhi?
A5: Hari berstatus HPE (Identitas) | B5: =Identitas!B20 -> Ya | C5: =IF(B5="Ya","Ya","Tidak") -> Ya
A6: Terjadi kontaminasi makanan/gagal penyaluran | B6: Tidak | C6: =IF(B6="Tidak","Ya","Tidak") -> Ya
A7: Terjadi kejadian fatal (keracunan) | B7: Tidak | C7: =IF(B7="Tidak","Ya","Tidak") -> Ya
A8: SPPG dalam status suspend | B8: Tidak | C8: =IF(B8="Tidak","Ya","Tidak") -> Ya
A9: Hasil verifikasi ketersediaan dan mutu layanan memenuhi | B9: Ya | C9: =IF(B9="Ya","Ya","Tidak") -> Ya
A10: Data penerima manfaat telah diinput pada SIPGN | B10: Ya | C10: =IF(B10="Ya","Ya","Tidak") -> Ya
A11: Insentif dapat diberikan | C11: =IF(COUNTIF(C5:C10,"Tidak")=0,"Ya","Tidak") -> Ya
A13: Penghitungan Insentif Hari Ini | C13: Nilai
A14: PM dihitung (A_PM) | C14: =A_PM!C47 -> 2339
A15: Tarif per PM per HPE (Rp) | C15: =Ref!B5 -> 2000
A16: Insentif dihitung hari ini (Rp) | C16: =IF(C11="Ya",C14*C15,0) -> 4678000
A18: Pembayaran Insentif ke Mitra/Yayasan (Hari Ini) | C18: Isian
A19: Nomor pernyataan besaran Insentif dari PPK | C19: PPK/INS/2026/XXXX
A20: Nilai pernyataan PPK (Rp) | C20: 4678000
A21: Nominal Insentif dibayarkan hari ini (Rp) | C21: 4678000
A22: Tanggal pembayaran | C22: 46300
A23: Nomor bukti pembayaran (unik) | C23: BYR-INS-001
A24: Nomor kuitansi | C24: KW-INS-001
A25: Kuitansi ditandatangani Mitra (Ya/Tidak) | C25: Ya
A26: Link PDF bukti bayar (Cloud SIPGN) | C26: https://cloud-sipgn.contoh/lpdh/insentif/BYR-INS-001.pdf
A27: Referensi transaksi VA (maker: Mitra; approver: Kepala SPPG) | C27: TRX-XXXXXX
A28: Kode unik transaksi (otomatis) | C28: =IF(N(C21)=0,"",Identitas!$B$6&"-"&TEXT(Identitas!$B$15,"yyyymmdd")&"-INS-"&TEXT(1,"000")) -> 18.71.XX.XXXX-20261005-INS-001
A30: Pemeriksaan Pembayaran | C30: Hasil
A31: Selisih pembayaran thd pernyataan PPK (Rp) | C31: =C21-C20 -> 0
A32: Status nomor bukti | C32: =IF(C23="","",IF(COUNTIF(I_RegisterBukti!$C$5:$C$130,C23)>1,"DUPLIKAT","Unik")) -> Unik
A33: Status tanggal pembayaran | C33: =IF(C21="","",IF(C22="","TANGGAL KOSONG",IF(AND(C22>=Identitas!$B$32,C22<=Identitas!$B$33),"Sesuai","DI LUAR PERIODE"))) -> Sesuai
A34: Status bukti autentik (nomor bukti, kuitansi bertanda tangan, link PDF) | C34: =IF(N(C21)=0,"",IF(AND(C23<>"",C24<>"",C25="Ya",LEFT(C26,8)="https://"),"Lengkap","BELUM LENGKAP")) -> Lengkap
A36: Pembayaran mengikuti nilai pernyataan PPK (dapat berbeda dari Insentif dihitung hari ini bila pernyataan PPK untuk HPE sebelumnya).

Sheet E_Saldo
A1: E. POSISI SALDO PER KOMPONEN DAN BUKTI PENERIMAAN TOP UP
A2: Top up yang diterima wajib didukung kuitansi/bukti terima dengan nilai dan tanggal. Jumlah saldo akhir wajib sama dengan saldo VA pada mutasi rekening.
A4: Komponen | B4: Saldo Awal (Rp) | C4: Top Up Diterima Hari Ini (Rp) | D4: Pengeluaran/Pembayaran Hari Ini (Rp) | E4: Saldo Akhir (Rp) | F4: Keterangan
A5: Biaya Bahan Baku Pangan | B5: 250000000 | C5: =E24 -> 20000000 | D5: =B_BahanBaku!I46 -> 18885000 | E5: =B5+C5-D5 -> 251115000
A6: Biaya Operasional | B6: 90000000 | C6: =F24 -> 7000000 | D6: =C_Operasional!H22 -> 6790000 | E6: =B6+C6-D6 -> 90210000
A7: Insentif Ketersediaan dan Mutu Layanan | B7: 25000000 | C7: =G24 -> 5000000 | D7: =D_Insentif!C21 -> 4678000 | E7: =B7+C7-D7 -> 25322000
A8: JUMLAH | B8: =SUM(B5:B7) -> 365000000 | C8: =SUM(C5:C7) -> 32000000 | D8: =SUM(D5:D7) -> 30353000 | E8: =SUM(E5:E7) -> 366647000
A10: Saldo VA menurut mutasi rekening (Rp) | E10: 366647000
A11: Selisih (saldo komponen − saldo VA) | E11: =IF(E10="","",E8-E10) -> 0
A12: Penjelasan selisih (wajib bila tidak nol)
A14: Informasi: Insentif dihitung hari ini (kewajiban, D_Insentif) | E14: =D_Insentif!C16 -> 4678000
A16: Dana bahan baku dan operasional tidak boleh dipakai untuk Insentif; pergeseran bahan baku ↔ operasional hanya dengan persetujuan tertulis PPK.
A18: No | B18: Kode Unik Transaksi (otomatis) | C18: Tanggal Diterima di VA | D18: No. SP2D/Referensi Top Up PPK | E18: Bahan Baku (Rp) | F18: Operasional (Rp) | G18: Insentif (Rp) | H18: Total Diterima (Rp) | I18: No. Kuitansi/Bukti Terima | J18: Link Bukti Terima (Cloud SIPGN) | K18: Status Nomor Bukti | L18: Status Tanggal | M18: Status Bukti
A19: 1 | B19: =IF(N(H19)=0,"",Identitas!$B$6&"-"&TEXT(Identitas!$B$15,"yyyymmdd")&"-TU-"&TEXT(A19,"000")) -> 18.71.XX.XXXX-20261005-TU-001 | C19: 46300 | D19: SP2D-XXXX/2026 | E19: 20000000 | F19: 7000000 | G19: 5000000 | H19: =SUM(E19:G19) -> 32000000 | I19: KW-TU-001 | J19: https://cloud-sipgn.contoh/lpdh/topup/KW-TU-001.pdf | K19: =IF(I19="","",IF(COUNTIF(I_RegisterBukti!$C$5:$C$130,I19)>1,"DUPLIKAT","Unik")) -> Unik | L19: =IF(N(H19)=0,"",IF(C19="","TANGGAL KOSONG",IF(AND(C19>=Identitas!$B$32,C19<=Identitas!$B$33),"Sesuai","DI LUAR PERIODE"))) -> Sesuai | M19: =IF(N(H19)=0,"",IF(AND(C19<>"",I19<>"",LEFT(J19,8)="https://"),"Lengkap","BELUM LENGKAP")) -> Lengkap
A20: 2 | B20: =IF(N(H20)=0,"",Identitas!$B$6&"-"&TEXT(Identitas!$B$15,"yyyymmdd")&"-TU-"&TEXT(A20,"000")) | H20: =SUM(E20:G20) -> 0 | K20: =IF(I20="","",IF(COUNTIF(I_RegisterBukti!$C$5:$C$130,I20)>1,"DUPLIKAT","Unik")) | L20: =IF(N(H20)=0,"",IF(C20="","TANGGAL KOSONG",IF(AND(C20>=Identitas!$B$32,C20<=Identitas!$B$33),"Sesuai","DI LUAR PERIODE"))) | M20: =IF(N(H20)=0,"",IF(AND(C20<>"",I20<>"",LEFT(J20,8)="https://"),"Lengkap","BELUM LENGKAP"))
A21: 3 | B21: =IF(N(H21)=0,"",Identitas!$B$6&"-"&TEXT(Identitas!$B$15,"yyyymmdd")&"-TU-"&TEXT(A21,"000")) | H21: =SUM(E21:G21) -> 0 | K21: =IF(I21="","",IF(COUNTIF(I_RegisterBukti!$C$5:$C$130,I21)>1,"DUPLIKAT","Unik")) | L21: =IF(N(H21)=0,"",IF(C21="","TANGGAL KOSONG",IF(AND(C21>=Identitas!$B$32,C21<=Identitas!$B$33),"Sesuai","DI LUAR PERIODE"))) | M21: =IF(N(H21)=0,"",IF(AND(C21<>"",I21<>"",LEFT(J21,8)="https://"),"Lengkap","BELUM LENGKAP"))
A22: 4 | B22: =IF(N(H22)=0,"",Identitas!$B$6&"-"&TEXT(Identitas!$B$15,"yyyymmdd")&"-TU-"&TEXT(A22,"000")) | H22: =SUM(E22:G22) -> 0 | K22: =IF(I22="","",IF(COUNTIF(I_RegisterBukti!$C$5:$C$130,I22)>1,"DUPLIKAT","Unik")) | L22: =IF(N(H22)=0,"",IF(C22="","TANGGAL KOSONG",IF(AND(C22>=Identitas!$B$32,C22<=Identitas!$B$33),"Sesuai","DI LUAR PERIODE"))) | M22: =IF(N(H22)=0,"",IF(AND(C22<>"",I22<>"",LEFT(J22,8)="https://"),"Lengkap","BELUM LENGKAP"))
A23: 5 | B23: =IF(N(H23)=0,"",Identitas!$B$6&"-"&TEXT(Identitas!$B$15,"yyyymmdd")&"-TU-"&TEXT(A23,"000")) | H23: =SUM(E23:G23) -> 0 | K23: =IF(I23="","",IF(COUNTIF(I_RegisterBukti!$C$5:$C$130,I23)>1,"DUPLIKAT","Unik")) | L23: =IF(N(H23)=0,"",IF(C23="","TANGGAL KOSONG",IF(AND(C23>=Identitas!$B$32,C23<=Identitas!$B$33),"Sesuai","DI LUAR PERIODE"))) | M23: =IF(N(H23)=0,"",IF(AND(C23<>"",I23<>"",LEFT(J23,8)="https://"),"Lengkap","BELUM LENGKAP"))
A24: JUMLAH | E24: =SUM(E19:E23) -> 20000000 | F24: =SUM(F19:F23) -> 7000000 | G24: =SUM(G19:G23) -> 5000000 | H24: =SUM(H19:H23) -> 32000000

Sheet F_TopUp
A1: F. USULAN DAN PERSETUJUAN TOP UP
A2: Kolom biru diisi Tim PPK berdasarkan hasil analisis LPDH.
A4: Komponen | B4: Usulan SPPG atas Hari Ini (Rp) | C4: Disetujui PPK (Rp) | D4: Selisih (Rp) | E4: Catatan Analisis PPK
A5: Biaya Bahan Baku Pangan | B5: =B_BahanBaku!I46 -> 18885000 | D5: =IF(C5="","",C5-B5)
A6: Biaya Operasional | B6: =C_Operasional!H22 -> 6790000 | D6: =IF(C6="","",C6-B6)
A7: Insentif Ketersediaan dan Mutu Layanan | B7: =D_Insentif!C16 -> 4678000 | D7: =IF(C7="","",C7-B7)
A8: JUMLAH | B8: =SUM(B5:B7) -> 30353000 | C8: =SUM(C5:C7) -> 0 | D8: =SUM(D5:D7) -> 0
A10: Ruang top up s.d. batas saldo VA (Rp) | C10: =MAX(0,Ref!B9-E_Saldo!E8) -> 133353000
A11: Usulan dalam batas saldo VA? | C11: =IF(B8<=C10,"Ya","Melebihi batas: sesuaikan") -> Ya
A13: Nama/NIP verifikator PPK
A14: Tanggal verifikasi

Sheet G_CekPPK
A1: G. DAFTAR PERIKSA OTOMATIS UNTUK TIM PPK
A2: OK = sesuai; PERIKSA = perlu klarifikasi atau perbaikan sebelum top up diproses.
A4: No | B4: Pemeriksaan | C4: Hasil | D4: Dasar
A5: 1 | B5: Identitas wajib terisi (ID SPPG, nama, tanggal, VA) | C5: =IF(COUNTA(Identitas!B6,Identitas!B7,Identitas!B13,Identitas!B15)=4,"OK","PERIKSA") -> OK | D5: SE E.6
A6: 2 | B6: Hari berstatus HPE dan HPE ke- tidak lebih dari 5 | C6: =IF(Identitas!B20="Ya","OK","PERIKSA") -> OK | D6: Perban 13/2026 Ps. 3
A7: 3 | B7: Produksi POP seimbang (distribusi + organoleptik + sampel + tidak terdistribusi + buffer) | C7: =IF(A_PM!C26=0,"OK","PERIKSA") -> OK | D7: Aplikasi POP
A8: 4 | B8: Distribusi POP sesuai penerimaan Fleet (per baris dan total) | C8: =IF(AND(A_PM!C41=0,SUMPRODUCT((A_PM!J6:J15<>0)*1)=0),"OK","PERIKSA") -> OK | D8: Aplikasi POP dan Fleet
A9: 5 | B9: Porsi tidak diterima seluruhnya diberi alasan | C9: =IF(SUMPRODUCT((A_PM!H6:H15>0)*(A_PM!I6:I15=""))=0,"OK","PERIKSA") -> OK | D9: Aplikasi Fleet
A10: 6 | B10: Buffer produksi dalam batas yang ditetapkan | C10: =IF(Ref!B12="","BELUM DITETAPKAN",IF(A_PM!C27<=Ref!B12,"OK","PERIKSA")) -> BELUM DITETAPKAN | D10: Ditetapkan PPK
A11: 7 | B11: Kelompok yang menerima porsi memiliki BNBA dan nomor BAST | C11: =IF(SUMPRODUCT((A_PM!G6:G15>0)*((A_PM!K6:K15<>"Ya")+(A_PM!L6:L15="")>0))=0,"OK","PERIKSA") -> OK | D11: SE E.4.f
A12: 8 | B12: Bukti autentik BAST ter-link ke Cloud SIPGN | C12: =IF(A_PM!C52=0,"OK","PERIKSA") -> OK | D12: Koreksi Tim PPK
